<?xml version="1.0" encoding="UTF-8"?>
<testng-results skipped="0" failed="1" ignored="0" total="1" passed="0">
  <reporter-output>
  </reporter-output>
  <suite name="Default suite" duration-ms="44401" started-at="2017-04-11T12:22:29Z" finished-at="2017-04-11T12:23:13Z">
    <groups>
    </groups>
    <test name="Default test" duration-ms="44401" started-at="2017-04-11T12:22:29Z" finished-at="2017-04-11T12:23:13Z">
      <class name="com.test.testcases.LoginTest">
        <test-method status="PASS" signature="before()[pri:0, instance:com.test.testcases.LoginTest@5700d6b1]" name="before" is-config="true" duration-ms="22168" started-at="2017-04-11T17:52:29Z" finished-at="2017-04-11T17:52:51Z">
          <reporter-output>
          </reporter-output>
        </test-method> <!-- before -->
        <test-method status="FAIL" signature="Check_whether_user_is_able_to_login_without_any_issues()[pri:0, instance:com.test.testcases.LoginTest@5700d6b1]" name="Check_whether_user_is_able_to_login_without_any_issues" duration-ms="22208" started-at="2017-04-11T17:52:51Z" finished-at="2017-04-11T17:53:13Z">
          <exception class="java.lang.AssertionError">
            <message>
              <![CDATA[expected:<true> but was:<false>]]>
            </message>
            <full-stacktrace>
              <![CDATA[java.lang.AssertionError: expected:<true> but was:<false>
	at org.junit.Assert.fail(Assert.java:88)
	at org.junit.Assert.failNotEquals(Assert.java:834)
	at org.junit.Assert.assertEquals(Assert.java:118)
	at org.junit.Assert.assertEquals(Assert.java:144)
	at com.test.testcases.LoginTest.Check_whether_user_is_able_to_login_without_any_issues(LoginTest.java:62)
	at sun.reflect.NativeMethodAccessorImpl.invoke0(Native Method)
	at sun.reflect.NativeMethodAccessorImpl.invoke(NativeMethodAccessorImpl.java:62)
	at sun.reflect.DelegatingMethodAccessorImpl.invoke(DelegatingMethodAccessorImpl.java:43)
	at java.lang.reflect.Method.invoke(Method.java:498)
	at org.testng.internal.MethodInvocationHelper.invokeMethod(MethodInvocationHelper.java:104)
	at org.testng.internal.Invoker.invokeMethod(Invoker.java:645)
	at org.testng.internal.Invoker.invokeTestMethod(Invoker.java:851)
	at org.testng.internal.Invoker.invokeTestMethods(Invoker.java:1177)
	at org.testng.internal.TestMethodWorker.invokeTestMethods(TestMethodWorker.java:129)
	at org.testng.internal.TestMethodWorker.run(TestMethodWorker.java:112)
	at org.testng.TestRunner.privateRun(TestRunner.java:756)
	at org.testng.TestRunner.run(TestRunner.java:610)
	at org.testng.SuiteRunner.runTest(SuiteRunner.java:387)
	at org.testng.SuiteRunner.runSequentially(SuiteRunner.java:382)
	at org.testng.SuiteRunner.privateRun(SuiteRunner.java:340)
	at org.testng.SuiteRunner.run(SuiteRunner.java:289)
	at org.testng.SuiteRunnerWorker.runSuite(SuiteRunnerWorker.java:52)
	at org.testng.SuiteRunnerWorker.run(SuiteRunnerWorker.java:86)
	at org.testng.TestNG.runSuitesSequentially(TestNG.java:1293)
	at org.testng.TestNG.runSuitesLocally(TestNG.java:1218)
	at org.testng.TestNG.runSuites(TestNG.java:1133)
	at org.testng.TestNG.run(TestNG.java:1104)
	at org.testng.remote.AbstractRemoteTestNG.run(AbstractRemoteTestNG.java:132)
	at org.testng.remote.RemoteTestNG.initAndRun(RemoteTestNG.java:236)
	at org.testng.remote.RemoteTestNG.main(RemoteTestNG.java:81)
]]>
            </full-stacktrace>
          </exception> <!-- java.lang.AssertionError -->
          <reporter-output>
          </reporter-output>
        </test-method> <!-- Check_whether_user_is_able_to_login_without_any_issues -->
      </class> <!-- com.test.testcases.LoginTest -->
    </test> <!-- Default test -->
  </suite> <!-- Default suite -->
</testng-results>
