<?xml version="1.0" encoding="UTF-8"?>
<testng-results skipped="0" failed="2" ignored="1" total="4" passed="1">
  <reporter-output>
  </reporter-output>
  <suite name="Default suite" duration-ms="134" started-at="2017-03-31T05:02:27Z" finished-at="2017-03-31T05:02:27Z">
    <groups>
    </groups>
    <test name="Default test" duration-ms="134" started-at="2017-03-31T05:02:27Z" finished-at="2017-03-31T05:02:27Z">
      <class name="com.test.testcases.LoginTest">
        <test-method status="FAIL" signature="Sample_test_method_to_test_the_report_process()[pri:0, instance:com.test.testcases.LoginTest@6fd02e5]" name="Sample_test_method_to_test_the_report_process" duration-ms="12" started-at="2017-03-31T10:32:27Z" finished-at="2017-03-31T10:32:27Z">
          <exception class="java.lang.AssertionError">
            <message>
              <![CDATA[expected [false] but found [true]]]>
            </message>
            <full-stacktrace>
              <![CDATA[java.lang.AssertionError: expected [false] but found [true]
	at org.testng.Assert.fail(Assert.java:94)
	at org.testng.Assert.failNotEquals(Assert.java:513)
	at org.testng.Assert.assertEqualsImpl(Assert.java:135)
	at org.testng.Assert.assertEquals(Assert.java:116)
	at org.testng.Assert.assertEquals(Assert.java:305)
	at org.testng.Assert.assertEquals(Assert.java:315)
	at com.test.testcases.LoginTest.Sample_test_method_to_test_the_report_process(LoginTest.java:41)
	at sun.reflect.NativeMethodAccessorImpl.invoke0(Native Method)
	at sun.reflect.NativeMethodAccessorImpl.invoke(NativeMethodAccessorImpl.java:62)
	at sun.reflect.DelegatingMethodAccessorImpl.invoke(DelegatingMethodAccessorImpl.java:43)
	at java.lang.reflect.Method.invoke(Method.java:498)
	at org.testng.internal.MethodInvocationHelper.invokeMethod(MethodInvocationHelper.java:104)
	at org.testng.internal.Invoker.invokeMethod(Invoker.java:645)
	at org.testng.internal.Invoker.invokeTestMethod(Invoker.java:851)
	at org.testng.internal.Invoker.invokeTestMethods(Invoker.java:1177)
	at org.testng.internal.TestMethodWorker.invokeTestMethods(TestMethodWorker.java:129)
	at org.testng.internal.TestMethodWorker.run(TestMethodWorker.java:112)
	at org.testng.TestRunner.privateRun(TestRunner.java:756)
	at org.testng.TestRunner.run(TestRunner.java:610)
	at org.testng.SuiteRunner.runTest(SuiteRunner.java:387)
	at org.testng.SuiteRunner.runSequentially(SuiteRunner.java:382)
	at org.testng.SuiteRunner.privateRun(SuiteRunner.java:340)
	at org.testng.SuiteRunner.run(SuiteRunner.java:289)
	at org.testng.SuiteRunnerWorker.runSuite(SuiteRunnerWorker.java:52)
	at org.testng.SuiteRunnerWorker.run(SuiteRunnerWorker.java:86)
	at org.testng.TestNG.runSuitesSequentially(TestNG.java:1293)
	at org.testng.TestNG.runSuitesLocally(TestNG.java:1218)
	at org.testng.TestNG.runSuites(TestNG.java:1133)
	at org.testng.TestNG.run(TestNG.java:1104)
	at org.testng.remote.AbstractRemoteTestNG.run(AbstractRemoteTestNG.java:132)
	at org.testng.remote.RemoteTestNG.initAndRun(RemoteTestNG.java:236)
	at org.testng.remote.RemoteTestNG.main(RemoteTestNG.java:81)
]]>
            </full-stacktrace>
          </exception> <!-- java.lang.AssertionError -->
          <reporter-output>
          </reporter-output>
        </test-method> <!-- Sample_test_method_to_test_the_report_process -->
        <test-method status="FAIL" signature="Sample_test_method_to_test_the_report_process3()[pri:1, instance:com.test.testcases.LoginTest@6fd02e5]" name="Sample_test_method_to_test_the_report_process3" duration-ms="1" started-at="2017-03-31T10:32:27Z" finished-at="2017-03-31T10:32:27Z">
          <exception class="java.lang.AssertionError">
            <message>
              <![CDATA[expected [e] but found [a]]]>
            </message>
            <full-stacktrace>
              <![CDATA[java.lang.AssertionError: expected [e] but found [a]
	at org.testng.Assert.fail(Assert.java:94)
	at org.testng.Assert.failNotEquals(Assert.java:513)
	at org.testng.Assert.assertEqualsImpl(Assert.java:135)
	at org.testng.Assert.assertEquals(Assert.java:116)
	at org.testng.Assert.assertEquals(Assert.java:190)
	at org.testng.Assert.assertEquals(Assert.java:200)
	at com.test.testcases.LoginTest.Sample_test_method_to_test_the_report_process3(LoginTest.java:51)
	at sun.reflect.NativeMethodAccessorImpl.invoke0(Native Method)
	at sun.reflect.NativeMethodAccessorImpl.invoke(NativeMethodAccessorImpl.java:62)
	at sun.reflect.DelegatingMethodAccessorImpl.invoke(DelegatingMethodAccessorImpl.java:43)
	at java.lang.reflect.Method.invoke(Method.java:498)
	at org.testng.internal.MethodInvocationHelper.invokeMethod(MethodInvocationHelper.java:104)
	at org.testng.internal.Invoker.invokeMethod(Invoker.java:645)
	at org.testng.internal.Invoker.invokeTestMethod(Invoker.java:851)
	at org.testng.internal.Invoker.invokeTestMethods(Invoker.java:1177)
	at org.testng.internal.TestMethodWorker.invokeTestMethods(TestMethodWorker.java:129)
	at org.testng.internal.TestMethodWorker.run(TestMethodWorker.java:112)
	at org.testng.TestRunner.privateRun(TestRunner.java:756)
	at org.testng.TestRunner.run(TestRunner.java:610)
	at org.testng.SuiteRunner.runTest(SuiteRunner.java:387)
	at org.testng.SuiteRunner.runSequentially(SuiteRunner.java:382)
	at org.testng.SuiteRunner.privateRun(SuiteRunner.java:340)
	at org.testng.SuiteRunner.run(SuiteRunner.java:289)
	at org.testng.SuiteRunnerWorker.runSuite(SuiteRunnerWorker.java:52)
	at org.testng.SuiteRunnerWorker.run(SuiteRunnerWorker.java:86)
	at org.testng.TestNG.runSuitesSequentially(TestNG.java:1293)
	at org.testng.TestNG.runSuitesLocally(TestNG.java:1218)
	at org.testng.TestNG.runSuites(TestNG.java:1133)
	at org.testng.TestNG.run(TestNG.java:1104)
	at org.testng.remote.AbstractRemoteTestNG.run(AbstractRemoteTestNG.java:132)
	at org.testng.remote.RemoteTestNG.initAndRun(RemoteTestNG.java:236)
	at org.testng.remote.RemoteTestNG.main(RemoteTestNG.java:81)
]]>
            </full-stacktrace>
          </exception> <!-- java.lang.AssertionError -->
          <reporter-output>
          </reporter-output>
        </test-method> <!-- Sample_test_method_to_test_the_report_process3 -->
        <test-method status="PASS" signature="Sample_test_method_to_test_the_report_process2()[pri:2, instance:com.test.testcases.LoginTest@6fd02e5]" name="Sample_test_method_to_test_the_report_process2" duration-ms="2" started-at="2017-03-31T10:32:27Z" finished-at="2017-03-31T10:32:27Z">
          <reporter-output>
          </reporter-output>
        </test-method> <!-- Sample_test_method_to_test_the_report_process2 -->
        <test-method status="FAIL" signature="report()[pri:0, instance:com.test.testcases.LoginTest@6fd02e5]" name="report" is-config="true" duration-ms="0" started-at="2017-03-31T10:32:27Z" finished-at="2017-03-31T10:32:27Z">
          <exception class="java.io.FileNotFoundException">
            <message>
              <![CDATA[File '/Users/md.ashrafiftekhar/Documents/workspace/Sample_TestTest.html' does not exist]]>
            </message>
            <full-stacktrace>
              <![CDATA[java.io.FileNotFoundException: File '/Users/md.ashrafiftekhar/Documents/workspace/Sample_TestTest.html' does not exist
	at org.apache.commons.io.FileUtils.openInputStream(FileUtils.java:299)
	at org.apache.commons.io.FileUtils.readFileToString(FileUtils.java:1711)
	at org.apache.commons.io.FileUtils.readFileToString(FileUtils.java:1748)
	at com.test.utils.Reporting.writeToHTML(Reporting.java:124)
	at com.test.utils.Reporting.generate(Reporting.java:64)
	at com.test.testcases.LoginTest.report(LoginTest.java:58)
	at sun.reflect.NativeMethodAccessorImpl.invoke0(Native Method)
	at sun.reflect.NativeMethodAccessorImpl.invoke(NativeMethodAccessorImpl.java:62)
	at sun.reflect.DelegatingMethodAccessorImpl.invoke(DelegatingMethodAccessorImpl.java:43)
	at java.lang.reflect.Method.invoke(Method.java:498)
	at org.testng.internal.MethodInvocationHelper.invokeMethod(MethodInvocationHelper.java:104)
	at org.testng.internal.Invoker.invokeConfigurationMethod(Invoker.java:515)
	at org.testng.internal.Invoker.invokeConfigurations(Invoker.java:217)
	at org.testng.internal.Invoker.invokeConfigurations(Invoker.java:144)
	at org.testng.internal.TestMethodWorker.invokeAfterClassMethods(TestMethodWorker.java:217)
	at org.testng.internal.TestMethodWorker.run(TestMethodWorker.java:115)
	at org.testng.TestRunner.privateRun(TestRunner.java:756)
	at org.testng.TestRunner.run(TestRunner.java:610)
	at org.testng.SuiteRunner.runTest(SuiteRunner.java:387)
	at org.testng.SuiteRunner.runSequentially(SuiteRunner.java:382)
	at org.testng.SuiteRunner.privateRun(SuiteRunner.java:340)
	at org.testng.SuiteRunner.run(SuiteRunner.java:289)
	at org.testng.SuiteRunnerWorker.runSuite(SuiteRunnerWorker.java:52)
	at org.testng.SuiteRunnerWorker.run(SuiteRunnerWorker.java:86)
	at org.testng.TestNG.runSuitesSequentially(TestNG.java:1293)
	at org.testng.TestNG.runSuitesLocally(TestNG.java:1218)
	at org.testng.TestNG.runSuites(TestNG.java:1133)
	at org.testng.TestNG.run(TestNG.java:1104)
	at org.testng.remote.AbstractRemoteTestNG.run(AbstractRemoteTestNG.java:132)
	at org.testng.remote.RemoteTestNG.initAndRun(RemoteTestNG.java:236)
	at org.testng.remote.RemoteTestNG.main(RemoteTestNG.java:81)
]]>
            </full-stacktrace>
          </exception> <!-- java.io.FileNotFoundException -->
          <reporter-output>
          </reporter-output>
        </test-method> <!-- report -->
      </class> <!-- com.test.testcases.LoginTest -->
    </test> <!-- Default test -->
  </suite> <!-- Default suite -->
</testng-results>
